Workbook

Sheet All_India_Index_Upto_April23 (1
A1: Sector | B1: Year | C1: Month | D1: Cereals and products | E1: Meat and fish | F1: Egg | G1: Milk and products | H1: Oils and fats | I1: Fruits | J1: Vegetables | K1: Pulses and products | L1: Sugar and Confectionery | M1: Spices | N1: Non-alcoholic beverages | O1: Prepared meals, snacks, sweets etc. | P1: Food and beverages | Q1: Pan, tobacco and intoxicants | R1: Clothing | S1: Footwear | T1: Clothing and footwear | U1: Housing | V1: Fuel and light | W1: Household goods and services | X1: Health | Y1: Transport and communication | Z1: Recreation and amusement | AA1: Education | AB1: Personal care and effects | AC1: Miscellaneous | AD1: General index
A2: Rural | B2: 2013 | C2: January | D2: 107.5 | E2: 106.3 | F2: 108.1 | G2: 104.9 | H2: 106.1 | I2: 103.9 | J2: 101.9 | K2: 106.1 | L2: 106.8 | M2: 103.1 | N2: 104.8 | O2: 106.7 | P2: 105.5 | Q2: 105.1 | R2: 106.5 | S2: 105.8 | T2: 106.4 | U2: NA | V2: 105.5 | W2: 104.8 | X2: 104 | Y2: 103.3 | Z2: 103.4 | AA2: 103.8 | AB2: 104.7 | AC2: 104 | AD2: 105.1
A3: Urban | B3: 2013 | C3: January | D3: 110.5 | E3: 109.1 | F3: 113 | G3: 103.6 | H3: 103.4 | I3: 102.3 | J3: 102.9 | K3: 105.8 | L3: 105.1 | M3: 101.8 | N3: 105.1 | O3: 107.9 | P3: 105.9 | Q3: 105.2 | R3: 105.9 | S3: 105 | T3: 105.8 | U3: 100.3 | V3: 105.4 | W3: 104.8 | X3: 104.1 | Y3: 103.2 | Z3: 102.9 | AA3: 103.5 | AB3: 104.3 | AC3: 103.7 | AD3: 104
A4: Rural+Urban | B4: 2013 | C4: January | D4: 108.4 | E4: 107.3 | F4: 110 | G4: 104.4 | H4: 105.1 | I4: 103.2 | J4: 102.2 | K4: 106 | L4: 106.2 | M4: 102.7 | N4: 104.9 | O4: 107.3 | P4: 105.6 | Q4: 105.1 | R4: 106.3 | S4: 105.5 | T4: 106.2 | U4: 100.3 | V4: 105.5 | W4: 104.8 | X4: 104 | Y4: 103.2 | Z4: 103.1 | AA4: 103.6 | AB4: 104.5 | AC4: 103.9 | AD4: 104.6
A5: Rural | B5: 2013 | C5: February | D5: 109.2 | E5: 108.7 | F5: 110.2 | G5: 105.4 | H5: 106.7 | I5: 104 | J5: 102.4 | K5: 105.9 | L5: 105.7 | M5: 103.1 | N5: 105.1 | O5: 107.7 | P5: 106.3 | Q5: 105.6 | R5: 107.1 | S5: 106.3 | T5: 107 | U5: NA | V5: 106.2 | W5: 105.2 | X5: 104.4 | Y5: 103.9 | Z5: 104 | AA5: 104.1 | AB5: 104.6 | AC5: 104.4 | AD5: 105.8
A6: Urban | B6: 2013 | C6: February | D6: 112.9 | E6: 112.9 | F6: 116.9 | G6: 104 | H6: 103.5 | I6: 103.1 | J6: 104.9 | K6: 104.1 | L6: 103.8 | M6: 102.3 | N6: 106 | O6: 109 | P6: 107.2 | Q6: 106 | R6: 106.6 | S6: 105.5 | T6: 106.4 | U6: 100.4 | V6: 105.7 | W6: 105.2 | X6: 104.7 | Y6: 104.4 | Z6: 103.3 | AA6: 103.7 | AB6: 104.3 | AC6: 104.3 | AD6: 104.7
A7: Rural+Urban | B7: 2013 | C7: February | D7: 110.4 | E7: 110.2 | F7: 112.8 | G7: 104.9 | H7: 105.5 | I7: 103.6 | J7: 103.2 | K7: 105.3 | L7: 105.1 | M7: 102.8 | N7: 105.5 | O7: 108.3 | P7: 106.6 | Q7: 105.7 | R7: 106.9 | S7: 106 | T7: 106.8 | U7: 100.4 | V7: 106 | W7: 105.2 | X7: 104.5 | Y7: 104.2 | Z7: 103.6 | AA7: 103.9 | AB7: 104.5 | AC7: 104.4 | AD7: 105.3
A8: Rural | B8: 2013 | C8: March | D8: 110.2 | E8: 108.8 | F8: 109.9 | G8: 105.6 | H8: 106.2 | I8: 105.7 | J8: 101.4 | K8: 105.7 | L8: 105 | M8: 103.3 | N8: 105.6 | O8: 108.2 | P8: 106.6 | Q8: 106.5 | R8: 107.6 | S8: 106.8 | T8: 107.5 | U8: NA | V8: 106.1 | W8: 105.6 | X8: 104.7 | Y8: 104.6 | Z8: 104 | AA8: 104.3 | AB8: 104.3 | AC8: 104.6 | AD8: 106
A9: Urban | B9: 2013 | C9: March | D9: 113.9 | E9: 111.4 | F9: 113.2 | G9: 104.3 | H9: 102.7 | I9: 104.9 | J9: 103.8 | K9: 103.5 | L9: 102.6 | M9: 102.4 | N9: 107 | O9: 109.8 | P9: 107.3 | Q9: 106.8 | R9: 107.2 | S9: 106 | T9: 107 | U9: 100.4 | V9: 106 | W9: 105.7 | X9: 105.2 | Y9: 105.5 | Z9: 103.5 | AA9: 103.8 | AB9: 104.2 | AC9: 104.9 | AD9: 105
A10: Rural+Urban | B10: 2013 | C10: March | D10: 111.4 | E10: 109.7 | F10: 111.2 | G10: 105.1 | H10: 104.9 | I10: 105.3 | J10: 102.2 | K10: 105 | L10: 104.2 | M10: 103 | N10: 106.2 | O10: 108.9 | P10: 106.9 | Q10: 106.6 | R10: 107.4 | S10: 106.5 | T10: 107.3 | U10: 100.4 | V10: 106.1 | W10: 105.6 | X10: 104.9 | Y10: 105.1 | Z10: 103.7 | AA10: 104 | AB10: 104.3 | AC10: 104.7 | AD10: 105.5
A11: Rural | B11: 2013 | C11: April | D11: 110.2 | E11: 109.5 | F11: 106.9 | G11: 106.3 | H11: 105.7 | I11: 108.3 | J11: 103.4 | K11: 105.7 | L11: 104.2 | M11: 103.2 | N11: 106.5 | O11: 108.8 | P11: 107.1 | Q11: 107.1 | R11: 108.1 | S11: 107.4 | T11: 108 | U11: NA | V11: 106.5 | W11: 106.1 | X11: 105.1 | Y11: 104.4 | Z11: 104.5 | AA11: 104.8 | AB11: 102.7 | AC11: 104.6 | AD11: 106.4
A12: Urban | B12: 2013 | C12: April | D12: 114.6 | E12: 113.4 | F12: 106 | G12: 104.7 | H12: 102.1 | I12: 109.5 | J12: 109.7 | K12: 104.6 | L12: 102 | M12: 103.5 | N12: 108.2 | O12: 110.6 | P12: 108.8 | Q12: 108.5 | R12: 107.9 | S12: 106.4 | T12: 107.7 | U12: 100.5 | V12: 106.4 | W12: 106.5 | X12: 105.7 | Y12: 105 | Z12: 104 | AA12: 105.2 | AB12: 103.2 | AC12: 105.1 | AD12: 105.7
A13: Rural+Urban | B13: 2013 | C13: April | D13: 111.6 | E13: 110.9 | F13: 106.6 | G13: 105.7 | H13: 104.4 | I13: 108.9 | J13: 105.5 | K13: 105.3 | L13: 103.5 | M13: 103.3 | N13: 107.2 | O13: 109.6 | P13: 107.7 | Q13: 107.5 | R13: 108 | S13: 107 | T13: 107.9 | U13: 100.5 | V13: 106.5 | W13: 106.3 | X13: 105.3 | Y13: 104.7 | Z13: 104.2 | AA13: 105 | AB13: 102.9 | AC13: 104.8 | AD13: 106.1
A14: Rural | B14: 2013 | C14: May | D14: 110.9 | E14: 109.8 | F14: 105.9 | G14: 107.5 | H14: 105.3 | I14: 108.1 | J14: 107.3 | K14: 106.1 | L14: 103.7 | M14: 104 | N14: 107.4 | O14: 109.9 | P14: 108.1 | Q14: 108.1 | R14: 108.8 | S14: 107.9 | T14: 108.6 | U14: NA | V14: 107.5 | W14: 106.8 | X14: 105.7 | Y14: 104.1 | Z14: 105 | AA14: 105.5 | AB14: 102.1 | AC14: 104.8 | AD14: 107.2
A15: Urban | B15: 2013 | C15: May | D15: 115.4 | E15: 114.2 | F15: 102.7 | G15: 105.5 | H15: 101.5 | I15: 110.6 | J15: 123.7 | K15: 105.2 | L15: 101.9 | M15: 105 | N15: 109.1 | O15: 111.3 | P15: 111.1 | Q15: 109.8 | R15: 108.5 | S15: 106.7 | T15: 108.3 | U15: 100.5 | V15: 107.2 | W15: 107.1 | X15: 106.2 | Y15: 103.9 | Z15: 104.6 | AA15: 105.7 | AB15: 102.6 | AC15: 104.9 | AD15: 106.6
A16: Rural+Urban | B16: 2013 | C16: May | D16: 112.3 | E16: 111.3 | F16: 104.7 | G16: 106.8 | H16: 103.9 | I16: 109.3 | J16: 112.9 | K16: 105.8 | L16: 103.1 | M16: 104.3 | N16: 108.1 | O16: 110.5 | P16: 109.2 | Q16: 108.6 | R16: 108.7 | S16: 107.4 | T16: 108.5 | U16: 100.5 | V16: 107.4 | W16: 106.9 | X16: 105.9 | Y16: 104 | Z16: 104.8 | AA16: 105.6 | AB16: 102.3 | AC16: 104.8 | AD16: 106.9
A17: Rural | B17: 2013 | C17: June | D17: 112.3 | E17: 112.1 | F17: 108.1 | G17: 108.3 | H17: 105.9 | I17: 109.2 | J17: 118 | K17: 106.8 | L17: 104.1 | M17: 105.4 | N17: 108.2 | O17: 111 | P17: 110.6 | Q17: 109 | R17: 109.7 | S17: 108.8 | T17: 109.5 | U17: NA | V17: 108.5 | W17: 107.5 | X17: 106.3 | Y17: 105 | Z17: 105.6 | AA17: 106.5 | AB17: 102.5 | AC17: 105.5 | AD17: 108.9
A18: Urban | B18: 2013 | C18: June | D18: 117 | E18: 120.1 | F18: 112.5 | G18: 107.3 | H18: 101.3 | I18: 112.4 | J18: 143.6 | K18: 105.4 | L18: 101.4 | M18: 106.4 | N18: 110 | O18: 112.2 | P18: 115 | Q18: 110.9 | R18: 109.2 | S18: 107.2 | T18: 108.9 | U18: 106.6 | V18: 108 | W18: 107.7 | X18: 106.5 | Y18: 105.2 | Z18: 105.2 | AA18: 108.1 | AB18: 103.3 | AC18: 106.1 | AD18: 109.7
A19: Rural+Urban | B19: 2013 | C19: June | D19: 113.8 | E19: 114.9 | F19: 109.8 | G19: 107.9 | H19: 104.2 | I19: 110.7 | J19: 126.7 | K19: 106.3 | L19: 103.2 | M19: 105.7 | N19: 109 | O19: 111.6 | P19: 112.2 | Q19: 109.5 | R19: 109.5 | S19: 108.1 | T19: 109.3 | U19: 106.6 | V19: 108.3 | W19: 107.6 | X19: 106.4 | Y19: 105.1 | Z19: 105.4 | AA19: 107.4 | AB19: 102.8 | AC19: 105.8 | AD19: 109.3
A20: Rural | B20: 2013 | C20: July | D20: 113.4 | E20: 114.9 | F20: 110.5 | G20: 109.3 | H20: 106.2 | I20: 110.3 | J20: 129.2 | K20: 107.1 | L20: 104.3 | M20: 106.4 | N20: 109.1 | O20: 112.1 | P20: 113.1 | Q20: 109.8 | R20: 110.5 | S20: 109.5 | T20: 110.3 | U20: NA | V20: 109.5 | W20: 108.3 | X20: 106.9 | Y20: 106.8 | Z20: 106.4 | AA20: 107.8 | AB20: 102.5 | AC20: 106.5 | AD20: 110.7
A21: Urban | B21: 2013 | C21: July | D21: 117.8 | E21: 119.2 | F21: 114 | G21: 108.3 | H21: 101.1 | I21: 113.2 | J21: 160.9 | K21: 105.1 | L21: 101.3 | M21: 107.5 | N21: 110.4 | O21: 113.1 | P21: 117.5 | Q21: 111.7 | R21: 109.8 | S21: 107.8 | T21: 109.5 | U21: 107.7 | V21: 108.6 | W21: 108.1 | X21: 107.1 | Y21: 107.3 | Z21: 105.9 | AA21: 110.1 | AB21: 103.2 | AC21: 107.3 | AD21: 111.4
A22: Rural+Urban | B22: 2013 | C22: July | D22: 114.8 | E22: 116.4 | F22: 111.9 | G22: 108.9 | H22: 104.3 | I22: 111.7 | J22: 140 | K22: 106.4 | L22: 103.3 | M22: 106.8 | N22: 109.6 | O22: 112.6 | P22: 114.7 | Q22: 110.3 | R22: 110.2 | S22: 108.8 | T22: 110 | U22: 107.7 | V22: 109.2 | W22: 108.2 | X22: 107 | Y22: 107.1 | Z22: 106.1 | AA22: 109.1 | AB22: 102.8 | AC22: 106.9 | AD22: 111
A23: Rural | B23: 2013 | C23: August | D23: 114.3 | E23: 115.4 | F23: 111.1 | G23: 110 | H23: 106.4 | I23: 110.8 | J23: 138.9 | K23: 107.4 | L23: 104.1 | M23: 106.9 | N23: 109.7 | O23: 112.6 | P23: 114.9 | Q23: 110.7 | R23: 111.3 | S23: 110.2 | T23: 111.1 | U23: NA | V23: 109.9 | W23: 108.7 | X23: 107.5 | Y23: 107.8 | Z23: 106.8 | AA23: 108.7 | AB23: 105 | AC23: 107.5 | AD23: 112.1
A24: Urban | B24: 2013 | C24: August | D24: 118.3 | E24: 120.4 | F24: 112.7 | G24: 108.9 | H24: 101.1 | I24: 108.7 | J24: 177 | K24: 104.7 | L24: 101 | M24: 108.5 | N24: 110.9 | O24: 114.3 | P24: 119.6 | Q24: 112.4 | R24: 110.6 | S24: 108.3 | T24: 110.2 | U24: 108.9 | V24: 109.3 | W24: 108.7 | X24: 107.6 | Y24: 108.1 | Z24: 106.5 | AA24: 110.8 | AB24: 106 | AC24: 108.3 | AD24: 112.7
A25: Rural+Urban | B25: 2013 | C25: August | D25: 115.6 | E25: 117.2 | F25: 111.7 | G25: 109.6 | H25: 104.5 | I25: 109.8 | J25: 151.8 | K25: 106.5 | L25: 103.1 | M25: 107.4 | N25: 110.2 | O25: 113.4 | P25: 116.6 | Q25: 111.2 | R25: 111 | S25: 109.4 | T25: 110.7 | U25: 108.9 | V25: 109.7 | W25: 108.7 | X25: 107.5 | Y25: 108 | Z25: 106.6 | AA25: 109.9 | AB25: 105.4 | AC25: 107.9 | AD25: 112.4
A26: Rural | B26: 2013 | C26: September | D26: 115.4 | E26: 115.7 | F26: 111.7 | G26: 111 | H26: 107.4 | I26: 110.9 | J26: 154 | K26: 108.1 | L26: 104.2 | M26: 107.9 | N26: 110.4 | O26: 114 | P26: 117.8 | Q26: 111.7 | R26: 112.7 | S26: 111.4 | T26: 112.5 | U26: NA | V26: 111.1 | W26: 109.6 | X26: 108.3 | Y26: 109.3 | Z26: 107.7 | AA26: 109.8 | AB26: 106.7 | AC26: 108.7 | AD26: 114.2
A27: Urban | B27: 2013 | C27: September | D27: 118.6 | E27: 119.1 | F27: 113.2 | G27: 109.6 | H27: 101.7 | I27: 103.2 | J27: 174.3 | K27: 105.1 | L27: 100.8 | M27: 109.1 | N27: 111.1 | O27: 115.4 | P27: 119.2 | Q27: 112.9 | R27: 111.4 | S27: 109 | T27: 111.1 | U27: 109.7 | V27: 109.5 | W27: 109.6 | X27: 107.9 | Y27: 110.4 | Z27: 107.4 | AA27: 111.2 | AB27: 106.9 | AC27: 109.4 | AD27: 113.2
A28: Rural+Urban | B28: 2013 | C28: September | D28: 116.4 | E28: 116.9 | F28: 112.3 | G28: 110.5 | H28: 105.3 | I28: 107.3 | J28: 160.9 | K28: 107.1 | L28: 103.1 | M28: 108.3 | N28: 110.7 | O28: 114.6 | P28: 118.3 | Q28: 112 | R28: 112.2 | S28: 110.4 | T28: 111.9 | U28: 109.7 | V28: 110.5 | W28: 109.6 | X28: 108.1 | Y28: 109.9 | Z28: 107.5 | AA28: 110.6 | AB28: 106.8 | AC28: 109 | AD28: 113.7
A29: Rural | B29: 2013 | C29: October | D29: 116.3 | E29: 115.4 | F29: 112.6 | G29: 111.7 | H29: 107.7 | I29: 113.2 | J29: 164.9 | K29: 108.3 | L29: 103.9 | M29: 108.2 | N29: 111.1 | O29: 114.9 | P29: 119.8 | Q29: 112.2 | R29: 113.6 | S29: 112.3 | T29: 113.4 | U29: NA | V29: 111.6 | W29: 110.4 | X29: 108.9 | Y29: 109.3 | Z29: 108.3 | AA29: 110.2 | AB29: 107.5 | AC29: 109.1 | AD29: 115.5
A30: Urban | B30: 2013 | C30: October | D30: 118.9 | E30: 118.1 | F30: 114.5 | G30: 110.4 | H30: 102.3 | I30: 106.2 | J30: 183.5 | K30: 105.3 | L30: 100.2 | M30: 109.6 | N30: 111.4 | O30: 116 | P30: 120.8 | Q30: 113.5 | R30: 112.5 | S30: 109.7 | T30: 112 | U30: 110.5 | V30: 109.7 | W30: 110.2 | X30: 108.2 | Y30: 109.7 | Z30: 108 | AA30: 111.3 | AB30: 107.3 | AC30: 109.4 | AD30: 114
A31: Rural+Urban | B31: 2013 | C31: October | D31: 117.1 | E31: 116.3 | F31: 113.3 | G31: 111.2 | H31: 105.7 | I31: 109.9 | J31: 171.2 | K31: 107.3 | L31: 102.7 | M31: 108.7 | N31: 111.2 | O31: 115.4 | P31: 120.2 | Q31: 112.5 | R31: 113.2 | S31: 111.2 | T31: 112.8 | U31: 110.5 | V31: 110.9 | W31: 110.3 | X31: 108.6 | Y31: 109.5 | Z31: 108.1 | AA31: 110.8 | AB31: 107.4 | AC31: 109.2 | AD31: 114.8
A32: Rural | B32: 2013 | C32: November | D32: 117.3 | E32: 114.9 | F32: 116.2 | G32: 112.8 | H32: 108.9 | I32: 116.6 | J32: 178.1 | K32: 109.1 | L32: 103.6 | M32: 109 | N32: 111.8 | O32: 116 | P32: 122.5 | Q32: 112.8 | R32: 114.6 | S32: 113.1 | T32: 114.4 | U32: NA | V32: 112.6 | W32: 111.3 | X32: 109.7 | Y32: 109.6 | Z32: 108.7 | AA32: 111 | AB32: 108.2 | AC32: 109.8 | AD32: 117.4
A33: Urban | B33: 2013 | C33: November | D33: 119.8 | E33: 116.3 | F33: 122.6 | G33: 112 | H33: 103.2 | I33: 110 | J33: 192.8 | K33: 106.3 | L33: 99.5 | M33: 110.3 | N33: 111.8 | O33: 117.1 | P33: 122.9 | Q33: 114.1 | R33: 113.5 | S33: 110.3 | T33: 113 | U33: 111.1 | V33: 110 | W33: 110.9 | X33: 108.6 | Y33: 109.5 | Z33: 108.5 | AA33: 111.3 | AB33: 107.9 | AC33: 109.6 | AD33: 115
A34: Rural+Urban | B34: 2013 | C34: November | D34: 118.1 | E34: 115.4 | F34: 118.7 | G34: 112.5 | H34: 106.8 | I34: 113.5 | J34: 183.1 | K34: 108.2 | L34: 102.2 | M34: 109.4 | N34: 111.8 | O34: 116.5 | P34: 122.6 | Q34: 113.1 | R34: 114.2 | S34: 111.9 | T34: 113.8 | U34: 111.1 | V34: 111.6 | W34: 111.1 | X34: 109.3 | Y34: 109.5 | Z34: 108.6 | AA34: 111.2 | AB34: 108.1 | AC34: 109.7 | AD34: 116.3
A35: Rural | B35: 2013 | C35: December | D35: 118.4 | E35: 115.9 | F35: 120.4 | G35: 113.8 | H35: 109.5 | I35: 115.5 | J35: 145.7 | K35: 109.5 | L35: 102.9 | M35: 109.8 | N35: 112.1 | O35: 116.8 | P35: 118.7 | Q35: 113.6 | R35: 115.8 | S35: 114 | T35: 115.5 | U35: NA | V35: 112.8 | W35: 112.1 | X35: 110.1 | Y35: 109.9 | Z35: 109.2 | AA35: 111.6 | AB35: 108.1 | AC35: 110.1 | AD35: 115.5
A36: Urban | B36: 2013 | C36: December | D36: 120.5 | E36: 118.1 | F36: 128.5 | G36: 112.8 | H36: 103.4 | I36: 110.7 | J36: 144.8 | K36: 107.1 | L36: 98.6 | M36: 111.9 | N36: 112.1 | O36: 118.1 | P36: 117.8 | Q36: 115 | R36: 114.2 | S36: 110.9 | T36: 113.7 | U36: 110.7 | V36: 110.4 | W36: 111.3 | X36: 109 | Y36: 109.7 | Z36: 108.9 | AA36: 111.4 | AB36: 107.7 | AC36: 109.8 | AD36: 113.3
A37: Rural+Urban | B37: 2013 | C37: December | D37: 119.1 | E37: 116.7 | F37: 123.5 | G37: 113.4 | H37: 107.3 | I37: 113.3 | J37: 145.4 | K37: 108.7 | L37: 101.5 | M37: 110.5 | N37: 112.1 | O37: 117.4 | P37: 118.4 | Q37: 114 | R37: 115.2 | S37: 112.7 | T37: 114.8 | U37: 110.7 | V37: 111.9 | W37: 111.7 | X37: 109.7 | Y37: 109.8 | Z37: 109 | AA37: 111.5 | AB37: 107.9 | AC37: 110 | AD37: 114.5
A38: Rural | B38: 2014 | C38: January | D38: 118.9 | E38: 117.1 | F38: 120.5 | G38: 114.4 | H38: 109 | I38: 115.5 | J38: 123.9 | K38: 109.6 | L38: 101.8 | M38: 110.2 | N38: 112.4 | O38: 117.3 | P38: 116 | Q38: 114 | R38: 116.5 | S38: 114.5 | T38: 116.2 | U38: NA | V38: 113 | W38: 112.6 | X38: 110.6 | Y38: 110.5 | Z38: 109.6 | AA38: 111.8 | AB38: 108.3 | AC38: 110.6 | AD38: 114.2
A39: Urban | B39: 2014 | C39: January | D39: 121.2 | E39: 122 | F39: 129.9 | G39: 113.6 | H39: 102.9 | I39: 112.1 | J39: 118.9 | K39: 107.5 | L39: 96.9 | M39: 112.7 | N39: 112.1 | O39: 119 | P39: 115.5 | Q39: 115.7 | R39: 114.8 | S39: 111.3 | T39: 114.3 | U39: 111.6 | V39: 111 | W39: 111.9 | X39: 109.7 | Y39: 110.8 | Z39: 109.8 | AA39: 111.5 | AB39: 108 | AC39: 110.5 | AD39: 112.9
A40: Rural+Urban | B40: 2014 | C40: January | D40: 119.6 | E40: 118.8 | F40: 124.1 | G40: 114.1 | H40: 106.8 | I40: 113.9 | J40: 122.2 | K40: 108.9 | L40: 100.2 | M40: 111 | N40: 112.3 | O40: 118.1 | P40: 115.8 | Q40: 114.5 | R40: 115.8 | S40: 113.2 | T40: 115.4 | U40: 111.6 | V40: 112.2 | W40: 112.3 | X40: 110.3 | Y40: 110.7 | Z40: 109.7 | AA40: 111.6 | AB40: 108.2 | AC40: 110.6 | AD40: 113.6
...

Sheet Working_Data
A1: Sector | B1: Year | C1: Month | D1: Cereals and products | E1: Meat and fish | F1: Egg | G1: Milk and products | H1: Oils and fats | I1: Fruits | J1: Vegetables | K1: Pulses and products | L1: Sugar and Confectionery | M1: Spices | N1: Non-alcoholic beverages | O1: Prepared meals, snacks, sweets etc. | P1: Food and beverages | Q1: Pan, tobacco and intoxicants | R1: Clothing | S1: Footwear | T1: Clothing and footwear | U1: Housing | V1: Fuel and light | W1: Household goods and services | X1: Health | Y1: Transport and communication | Z1: Recreation and amusement | AA1: Education | AB1: Personal care and effects | AC1: Miscellaneous | AD1: General index
A2: Rural | B2: 2013 | C2: January | D2: 107.5 | E2: 106.3 | F2: 108.1 | G2: 104.9 | H2: 106.1 | I2: 103.9 | J2: 101.9 | K2: 106.1 | L2: 106.8 | M2: 103.1 | N2: 104.8 | O2: 106.7 | P2: 105.5 | Q2: 105.1 | R2: 106.5 | S2: 105.8 | T2: 106.4 | U2: NA | V2: 105.5 | W2: 104.8 | X2: 104 | Y2: 103.3 | Z2: 103.4 | AA2: 103.8 | AB2: 104.7 | AC2: 104 | AD2: 105.1
A3: Urban | B3: 2013 | C3: January | D3: 110.5 | E3: 109.1 | F3: 113 | G3: 103.6 | H3: 103.4 | I3: 102.3 | J3: 102.9 | K3: 105.8 | L3: 105.1 | M3: 101.8 | N3: 105.1 | O3: 107.9 | P3: 105.9 | Q3: 105.2 | R3: 105.9 | S3: 105 | T3: 105.8 | U3: 100.3 | V3: 105.4 | W3: 104.8 | X3: 104.1 | Y3: 103.2 | Z3: 102.9 | AA3: 103.5 | AB3: 104.3 | AC3: 103.7 | AD3: 104
A4: Rural+Urban | B4: 2013 | C4: January | D4: 108.4 | E4: 107.3 | F4: 110 | G4: 104.4 | H4: 105.1 | I4: 103.2 | J4: 102.2 | K4: 106 | L4: 106.2 | M4: 102.7 | N4: 104.9 | O4: 107.3 | P4: 105.6 | Q4: 105.1 | R4: 106.3 | S4: 105.5 | T4: 106.2 | U4: 100.3 | V4: 105.5 | W4: 104.8 | X4: 104 | Y4: 103.2 | Z4: 103.1 | AA4: 103.6 | AB4: 104.5 | AC4: 103.9 | AD4: 104.6
A5: Rural | B5: 2013 | C5: February | D5: 109.2 | E5: 108.7 | F5: 110.2 | G5: 105.4 | H5: 106.7 | I5: 104 | J5: 102.4 | K5: 105.9 | L5: 105.7 | M5: 103.1 | N5: 105.1 | O5: 107.7 | P5: 106.3 | Q5: 105.6 | R5: 107.1 | S5: 106.3 | T5: 107 | U5: NA | V5: 106.2 | W5: 105.2 | X5: 104.4 | Y5: 103.9 | Z5: 104 | AA5: 104.1 | AB5: 104.6 | AC5: 104.4 | AD5: 105.8
A6: Urban | B6: 2013 | C6: February | D6: 112.9 | E6: 112.9 | F6: 116.9 | G6: 104 | H6: 103.5 | I6: 103.1 | J6: 104.9 | K6: 104.1 | L6: 103.8 | M6: 102.3 | N6: 106 | O6: 109 | P6: 107.2 | Q6: 106 | R6: 106.6 | S6: 105.5 | T6: 106.4 | U6: 100.4 | V6: 105.7 | W6: 105.2 | X6: 104.7 | Y6: 104.4 | Z6: 103.3 | AA6: 103.7 | AB6: 104.3 | AC6: 104.3 | AD6: 104.7
A7: Rural+Urban | B7: 2013 | C7: February | D7: 110.4 | E7: 110.2 | F7: 112.8 | G7: 104.9 | H7: 105.5 | I7: 103.6 | J7: 103.2 | K7: 105.3 | L7: 105.1 | M7: 102.8 | N7: 105.5 | O7: 108.3 | P7: 106.6 | Q7: 105.7 | R7: 106.9 | S7: 106 | T7: 106.8 | U7: 100.4 | V7: 106 | W7: 105.2 | X7: 104.5 | Y7: 104.2 | Z7: 103.6 | AA7: 103.9 | AB7: 104.5 | AC7: 104.4 | AD7: 105.3
A8: Rural | B8: 2013 | C8: March | D8: 110.2 | E8: 108.8 | F8: 109.9 | G8: 105.6 | H8: 106.2 | I8: 105.7 | J8: 101.4 | K8: 105.7 | L8: 105 | M8: 103.3 | N8: 105.6 | O8: 108.2 | P8: 106.6 | Q8: 106.5 | R8: 107.6 | S8: 106.8 | T8: 107.5 | U8: NA | V8: 106.1 | W8: 105.6 | X8: 104.7 | Y8: 104.6 | Z8: 104 | AA8: 104.3 | AB8: 104.3 | AC8: 104.6 | AD8: 106
A9: Urban | B9: 2013 | C9: March | D9: 113.9 | E9: 111.4 | F9: 113.2 | G9: 104.3 | H9: 102.7 | I9: 104.9 | J9: 103.8 | K9: 103.5 | L9: 102.6 | M9: 102.4 | N9: 107 | O9: 109.8 | P9: 107.3 | Q9: 106.8 | R9: 107.2 | S9: 106 | T9: 107 | U9: 100.4 | V9: 106 | W9: 105.7 | X9: 105.2 | Y9: 105.5 | Z9: 103.5 | AA9: 103.8 | AB9: 104.2 | AC9: 104.9 | AD9: 105
A10: Rural+Urban | B10: 2013 | C10: March | D10: 111.4 | E10: 109.7 | F10: 111.2 | G10: 105.1 | H10: 104.9 | I10: 105.3 | J10: 102.2 | K10: 105 | L10: 104.2 | M10: 103 | N10: 106.2 | O10: 108.9 | P10: 106.9 | Q10: 106.6 | R10: 107.4 | S10: 106.5 | T10: 107.3 | U10: 100.4 | V10: 106.1 | W10: 105.6 | X10: 104.9 | Y10: 105.1 | Z10: 103.7 | AA10: 104 | AB10: 104.3 | AC10: 104.7 | AD10: 105.5
A11: Rural | B11: 2013 | C11: April | D11: 110.2 | E11: 109.5 | F11: 106.9 | G11: 106.3 | H11: 105.7 | I11: 108.3 | J11: 103.4 | K11: 105.7 | L11: 104.2 | M11: 103.2 | N11: 106.5 | O11: 108.8 | P11: 107.1 | Q11: 107.1 | R11: 108.1 | S11: 107.4 | T11: 108 | U11: NA | V11: 106.5 | W11: 106.1 | X11: 105.1 | Y11: 104.4 | Z11: 104.5 | AA11: 104.8 | AB11: 102.7 | AC11: 104.6 | AD11: 106.4
A12: Urban | B12: 2013 | C12: April | D12: 114.6 | E12: 113.4 | F12: 106 | G12: 104.7 | H12: 102.1 | I12: 109.5 | J12: 109.7 | K12: 104.6 | L12: 102 | M12: 103.5 | N12: 108.2 | O12: 110.6 | P12: 108.8 | Q12: 108.5 | R12: 107.9 | S12: 106.4 | T12: 107.7 | U12: 100.5 | V12: 106.4 | W12: 106.5 | X12: 105.7 | Y12: 105 | Z12: 104 | AA12: 105.2 | AB12: 103.2 | AC12: 105.1 | AD12: 105.7
A13: Rural+Urban | B13: 2013 | C13: April | D13: 111.6 | E13: 110.9 | F13: 106.6 | G13: 105.7 | H13: 104.4 | I13: 108.9 | J13: 105.5 | K13: 105.3 | L13: 103.5 | M13: 103.3 | N13: 107.2 | O13: 109.6 | P13: 107.7 | Q13: 107.5 | R13: 108 | S13: 107 | T13: 107.9 | U13: 100.5 | V13: 106.5 | W13: 106.3 | X13: 105.3 | Y13: 104.7 | Z13: 104.2 | AA13: 105 | AB13: 102.9 | AC13: 104.8 | AD13: 106.1
A14: Rural | B14: 2013 | C14: May | D14: 110.9 | E14: 109.8 | F14: 105.9 | G14: 107.5 | H14: 105.3 | I14: 108.1 | J14: 107.3 | K14: 106.1 | L14: 103.7 | M14: 104 | N14: 107.4 | O14: 109.9 | P14: 108.1 | Q14: 108.1 | R14: 108.8 | S14: 107.9 | T14: 108.6 | U14: NA | V14: 107.5 | W14: 106.8 | X14: 105.7 | Y14: 104.1 | Z14: 105 | AA14: 105.5 | AB14: 102.1 | AC14: 104.8 | AD14: 107.2
A15: Urban | B15: 2013 | C15: May | D15: 115.4 | E15: 114.2 | F15: 102.7 | G15: 105.5 | H15: 101.5 | I15: 110.6 | J15: 123.7 | K15: 105.2 | L15: 101.9 | M15: 105 | N15: 109.1 | O15: 111.3 | P15: 111.1 | Q15: 109.8 | R15: 108.5 | S15: 106.7 | T15: 108.3 | U15: 100.5 | V15: 107.2 | W15: 107.1 | X15: 106.2 | Y15: 103.9 | Z15: 104.6 | AA15: 105.7 | AB15: 102.6 | AC15: 104.9 | AD15: 106.6
A16: Rural+Urban | B16: 2013 | C16: May | D16: 112.3 | E16: 111.3 | F16: 104.7 | G16: 106.8 | H16: 103.9 | I16: 109.3 | J16: 112.9 | K16: 105.8 | L16: 103.1 | M16: 104.3 | N16: 108.1 | O16: 110.5 | P16: 109.2 | Q16: 108.6 | R16: 108.7 | S16: 107.4 | T16: 108.5 | U16: 100.5 | V16: 107.4 | W16: 106.9 | X16: 105.9 | Y16: 104 | Z16: 104.8 | AA16: 105.6 | AB16: 102.3 | AC16: 104.8 | AD16: 106.9
A17: Rural | B17: 2013 | C17: June | D17: 112.3 | E17: 112.1 | F17: 108.1 | G17: 108.3 | H17: 105.9 | I17: 109.2 | J17: 118 | K17: 106.8 | L17: 104.1 | M17: 105.4 | N17: 108.2 | O17: 111 | P17: 110.6 | Q17: 109 | R17: 109.7 | S17: 108.8 | T17: 109.5 | U17: NA | V17: 108.5 | W17: 107.5 | X17: 106.3 | Y17: 105 | Z17: 105.6 | AA17: 106.5 | AB17: 102.5 | AC17: 105.5 | AD17: 108.9
A18: Urban | B18: 2013 | C18: June | D18: 117 | E18: 120.1 | F18: 112.5 | G18: 107.3 | H18: 101.3 | I18: 112.4 | J18: 143.6 | K18: 105.4 | L18: 101.4 | M18: 106.4 | N18: 110 | O18: 112.2 | P18: 115 | Q18: 110.9 | R18: 109.2 | S18: 107.2 | T18: 108.9 | U18: 106.6 | V18: 108 | W18: 107.7 | X18: 106.5 | Y18: 105.2 | Z18: 105.2 | AA18: 108.1 | AB18: 103.3 | AC18: 106.1 | AD18: 109.7
A19: Rural+Urban | B19: 2013 | C19: June | D19: 113.8 | E19: 114.9 | F19: 109.8 | G19: 107.9 | H19: 104.2 | I19: 110.7 | J19: 126.7 | K19: 106.3 | L19: 103.2 | M19: 105.7 | N19: 109 | O19: 111.6 | P19: 112.2 | Q19: 109.5 | R19: 109.5 | S19: 108.1 | T19: 109.3 | U19: 106.6 | V19: 108.3 | W19: 107.6 | X19: 106.4 | Y19: 105.1 | Z19: 105.4 | AA19: 107.4 | AB19: 102.8 | AC19: 105.8 | AD19: 109.3
A20: Rural | B20: 2013 | C20: July | D20: 113.4 | E20: 114.9 | F20: 110.5 | G20: 109.3 | H20: 106.2 | I20: 110.3 | J20: 129.2 | K20: 107.1 | L20: 104.3 | M20: 106.4 | N20: 109.1 | O20: 112.1 | P20: 113.1 | Q20: 109.8 | R20: 110.5 | S20: 109.5 | T20: 110.3 | U20: NA | V20: 109.5 | W20: 108.3 | X20: 106.9 | Y20: 106.8 | Z20: 106.4 | AA20: 107.8 | AB20: 102.5 | AC20: 106.5 | AD20: 110.7
A21: Urban | B21: 2013 | C21: July | D21: 117.8 | E21: 119.2 | F21: 114 | G21: 108.3 | H21: 101.1 | I21: 113.2 | J21: 160.9 | K21: 105.1 | L21: 101.3 | M21: 107.5 | N21: 110.4 | O21: 113.1 | P21: 117.5 | Q21: 111.7 | R21: 109.8 | S21: 107.8 | T21: 109.5 | U21: 107.7 | V21: 108.6 | W21: 108.1 | X21: 107.1 | Y21: 107.3 | Z21: 105.9 | AA21: 110.1 | AB21: 103.2 | AC21: 107.3 | AD21: 111.4
A22: Rural+Urban | B22: 2013 | C22: July | D22: 114.8 | E22: 116.4 | F22: 111.9 | G22: 108.9 | H22: 104.3 | I22: 111.7 | J22: 140 | K22: 106.4 | L22: 103.3 | M22: 106.8 | N22: 109.6 | O22: 112.6 | P22: 114.7 | Q22: 110.3 | R22: 110.2 | S22: 108.8 | T22: 110 | U22: 107.7 | V22: 109.2 | W22: 108.2 | X22: 107 | Y22: 107.1 | Z22: 106.1 | AA22: 109.1 | AB22: 102.8 | AC22: 106.9 | AD22: 111
A23: Rural | B23: 2013 | C23: August | D23: 114.3 | E23: 115.4 | F23: 111.1 | G23: 110 | H23: 106.4 | I23: 110.8 | J23: 138.9 | K23: 107.4 | L23: 104.1 | M23: 106.9 | N23: 109.7 | O23: 112.6 | P23: 114.9 | Q23: 110.7 | R23: 111.3 | S23: 110.2 | T23: 111.1 | U23: NA | V23: 109.9 | W23: 108.7 | X23: 107.5 | Y23: 107.8 | Z23: 106.8 | AA23: 108.7 | AB23: 105 | AC23: 107.5 | AD23: 112.1
A24: Urban | B24: 2013 | C24: August | D24: 118.3 | E24: 120.4 | F24: 112.7 | G24: 108.9 | H24: 101.1 | I24: 108.7 | J24: 177 | K24: 104.7 | L24: 101 | M24: 108.5 | N24: 110.9 | O24: 114.3 | P24: 119.6 | Q24: 112.4 | R24: 110.6 | S24: 108.3 | T24: 110.2 | U24: 108.9 | V24: 109.3 | W24: 108.7 | X24: 107.6 | Y24: 108.1 | Z24: 106.5 | AA24: 110.8 | AB24: 106 | AC24: 108.3 | AD24: 112.7
A25: Rural+Urban | B25: 2013 | C25: August | D25: 115.6 | E25: 117.2 | F25: 111.7 | G25: 109.6 | H25: 104.5 | I25: 109.8 | J25: 151.8 | K25: 106.5 | L25: 103.1 | M25: 107.4 | N25: 110.2 | O25: 113.4 | P25: 116.6 | Q25: 111.2 | R25: 111 | S25: 109.4 | T25: 110.7 | U25: 108.9 | V25: 109.7 | W25: 108.7 | X25: 107.5 | Y25: 108 | Z25: 106.6 | AA25: 109.9 | AB25: 105.4 | AC25: 107.9 | AD25: 112.4
A26: Rural | B26: 2013 | C26: September | D26: 115.4 | E26: 115.7 | F26: 111.7 | G26: 111 | H26: 107.4 | I26: 110.9 | J26: 154 | K26: 108.1 | L26: 104.2 | M26: 107.9 | N26: 110.4 | O26: 114 | P26: 117.8 | Q26: 111.7 | R26: 112.7 | S26: 111.4 | T26: 112.5 | U26: NA | V26: 111.1 | W26: 109.6 | X26: 108.3 | Y26: 109.3 | Z26: 107.7 | AA26: 109.8 | AB26: 106.7 | AC26: 108.7 | AD26: 114.2
A27: Urban | B27: 2013 | C27: September | D27: 118.6 | E27: 119.1 | F27: 113.2 | G27: 109.6 | H27: 101.7 | I27: 103.2 | J27: 174.3 | K27: 105.1 | L27: 100.8 | M27: 109.1 | N27: 111.1 | O27: 115.4 | P27: 119.2 | Q27: 112.9 | R27: 111.4 | S27: 109 | T27: 111.1 | U27: 109.7 | V27: 109.5 | W27: 109.6 | X27: 107.9 | Y27: 110.4 | Z27: 107.4 | AA27: 111.2 | AB27: 106.9 | AC27: 109.4 | AD27: 113.2
A28: Rural+Urban | B28: 2013 | C28: September | D28: 116.4 | E28: 116.9 | F28: 112.3 | G28: 110.5 | H28: 105.3 | I28: 107.3 | J28: 160.9 | K28: 107.1 | L28: 103.1 | M28: 108.3 | N28: 110.7 | O28: 114.6 | P28: 118.3 | Q28: 112 | R28: 112.2 | S28: 110.4 | T28: 111.9 | U28: 109.7 | V28: 110.5 | W28: 109.6 | X28: 108.1 | Y28: 109.9 | Z28: 107.5 | AA28: 110.6 | AB28: 106.8 | AC28: 109 | AD28: 113.7
A29: Rural | B29: 2013 | C29: October | D29: 116.3 | E29: 115.4 | F29: 112.6 | G29: 111.7 | H29: 107.7 | I29: 113.2 | J29: 164.9 | K29: 108.3 | L29: 103.9 | M29: 108.2 | N29: 111.1 | O29: 114.9 | P29: 119.8 | Q29: 112.2 | R29: 113.6 | S29: 112.3 | T29: 113.4 | U29: NA | V29: 111.6 | W29: 110.4 | X29: 108.9 | Y29: 109.3 | Z29: 108.3 | AA29: 110.2 | AB29: 107.5 | AC29: 109.1 | AD29: 115.5
A30: Urban | B30: 2013 | C30: October | D30: 118.9 | E30: 118.1 | F30: 114.5 | G30: 110.4 | H30: 102.3 | I30: 106.2 | J30: 183.5 | K30: 105.3 | L30: 100.2 | M30: 109.6 | N30: 111.4 | O30: 116 | P30: 120.8 | Q30: 113.5 | R30: 112.5 | S30: 109.7 | T30: 112 | U30: 110.5 | V30: 109.7 | W30: 110.2 | X30: 108.2 | Y30: 109.7 | Z30: 108 | AA30: 111.3 | AB30: 107.3 | AC30: 109.4 | AD30: 114
A31: Rural+Urban | B31: 2013 | C31: October | D31: 117.1 | E31: 116.3 | F31: 113.3 | G31: 111.2 | H31: 105.7 | I31: 109.9 | J31: 171.2 | K31: 107.3 | L31: 102.7 | M31: 108.7 | N31: 111.2 | O31: 115.4 | P31: 120.2 | Q31: 112.5 | R31: 113.2 | S31: 111.2 | T31: 112.8 | U31: 110.5 | V31: 110.9 | W31: 110.3 | X31: 108.6 | Y31: 109.5 | Z31: 108.1 | AA31: 110.8 | AB31: 107.4 | AC31: 109.2 | AD31: 114.8
A32: Rural | B32: 2013 | C32: November | D32: 117.3 | E32: 114.9 | F32: 116.2 | G32: 112.8 | H32: 108.9 | I32: 116.6 | J32: 178.1 | K32: 109.1 | L32: 103.6 | M32: 109 | N32: 111.8 | O32: 116 | P32: 122.5 | Q32: 112.8 | R32: 114.6 | S32: 113.1 | T32: 114.4 | U32: NA | V32: 112.6 | W32: 111.3 | X32: 109.7 | Y32: 109.6 | Z32: 108.7 | AA32: 111 | AB32: 108.2 | AC32: 109.8 | AD32: 117.4
A33: Urban | B33: 2013 | C33: November | D33: 119.8 | E33: 116.3 | F33: 122.6 | G33: 112 | H33: 103.2 | I33: 110 | J33: 192.8 | K33: 106.3 | L33: 99.5 | M33: 110.3 | N33: 111.8 | O33: 117.1 | P33: 122.9 | Q33: 114.1 | R33: 113.5 | S33: 110.3 | T33: 113 | U33: 111.1 | V33: 110 | W33: 110.9 | X33: 108.6 | Y33: 109.5 | Z33: 108.5 | AA33: 111.3 | AB33: 107.9 | AC33: 109.6 | AD33: 115
A34: Rural+Urban | B34: 2013 | C34: November | D34: 118.1 | E34: 115.4 | F34: 118.7 | G34: 112.5 | H34: 106.8 | I34: 113.5 | J34: 183.1 | K34: 108.2 | L34: 102.2 | M34: 109.4 | N34: 111.8 | O34: 116.5 | P34: 122.6 | Q34: 113.1 | R34: 114.2 | S34: 111.9 | T34: 113.8 | U34: 111.1 | V34: 111.6 | W34: 111.1 | X34: 109.3 | Y34: 109.5 | Z34: 108.6 | AA34: 111.2 | AB34: 108.1 | AC34: 109.7 | AD34: 116.3
A35: Rural | B35: 2013 | C35: December | D35: 118.4 | E35: 115.9 | F35: 120.4 | G35: 113.8 | H35: 109.5 | I35: 115.5 | J35: 145.7 | K35: 109.5 | L35: 102.9 | M35: 109.8 | N35: 112.1 | O35: 116.8 | P35: 118.7 | Q35: 113.6 | R35: 115.8 | S35: 114 | T35: 115.5 | U35: NA | V35: 112.8 | W35: 112.1 | X35: 110.1 | Y35: 109.9 | Z35: 109.2 | AA35: 111.6 | AB35: 108.1 | AC35: 110.1 | AD35: 115.5
A36: Urban | B36: 2013 | C36: December | D36: 120.5 | E36: 118.1 | F36: 128.5 | G36: 112.8 | H36: 103.4 | I36: 110.7 | J36: 144.8 | K36: 107.1 | L36: 98.6 | M36: 111.9 | N36: 112.1 | O36: 118.1 | P36: 117.8 | Q36: 115 | R36: 114.2 | S36: 110.9 | T36: 113.7 | U36: 110.7 | V36: 110.4 | W36: 111.3 | X36: 109 | Y36: 109.7 | Z36: 108.9 | AA36: 111.4 | AB36: 107.7 | AC36: 109.8 | AD36: 113.3
A37: Rural+Urban | B37: 2013 | C37: December | D37: 119.1 | E37: 116.7 | F37: 123.5 | G37: 113.4 | H37: 107.3 | I37: 113.3 | J37: 145.4 | K37: 108.7 | L37: 101.5 | M37: 110.5 | N37: 112.1 | O37: 117.4 | P37: 118.4 | Q37: 114 | R37: 115.2 | S37: 112.7 | T37: 114.8 | U37: 110.7 | V37: 111.9 | W37: 111.7 | X37: 109.7 | Y37: 109.8 | Z37: 109 | AA37: 111.5 | AB37: 107.9 | AC37: 110 | AD37: 114.5
A38: Rural | B38: 2014 | C38: January | D38: 118.9 | E38: 117.1 | F38: 120.5 | G38: 114.4 | H38: 109 | I38: 115.5 | J38: 123.9 | K38: 109.6 | L38: 101.8 | M38: 110.2 | N38: 112.4 | O38: 117.3 | P38: 116 | Q38: 114 | R38: 116.5 | S38: 114.5 | T38: 116.2 | U38: NA | V38: 113 | W38: 112.6 | X38: 110.6 | Y38: 110.5 | Z38: 109.6 | AA38: 111.8 | AB38: 108.3 | AC38: 110.6 | AD38: 114.2
A39: Urban | B39: 2014 | C39: January | D39: 121.2 | E39: 122 | F39: 129.9 | G39: 113.6 | H39: 102.9 | I39: 112.1 | J39: 118.9 | K39: 107.5 | L39: 96.9 | M39: 112.7 | N39: 112.1 | O39: 119 | P39: 115.5 | Q39: 115.7 | R39: 114.8 | S39: 111.3 | T39: 114.3 | U39: 111.6 | V39: 111 | W39: 111.9 | X39: 109.7 | Y39: 110.8 | Z39: 109.8 | AA39: 111.5 | AB39: 108 | AC39: 110.5 | AD39: 112.9
A40: Rural+Urban | B40: 2014 | C40: January | D40: 119.6 | E40: 118.8 | F40: 124.1 | G40: 114.1 | H40: 106.8 | I40: 113.9 | J40: 122.2 | K40: 108.9 | L40: 100.2 | M40: 111 | N40: 112.3 | O40: 118.1 | P40: 115.8 | Q40: 114.5 | R40: 115.8 | S40: 113.2 | T40: 115.4 | U40: 111.6 | V40: 112.2 | W40: 112.3 | X40: 110.3 | Y40: 110.7 | Z40: 109.7 | AA40: 111.6 | AB40: 108.2 | AC40: 110.6 | AD40: 113.6
...

Sheet Problem_Statement

Sheet 1.CPI Contribution Analysis
C1: Consumer Price Index (CPI) data, Government of India
C2: Reference Month: May 2023
B3: Sector | C3: Year | D3: Month | E3: Cereals and products | F3: Meat and fish | G3: Egg | H3: Milk and products | I3: Oils and fats | J3: Fruits | K3: Vegetables | L3: Pulses and products | M3: Sugar and Confectionery | N3: Spices | O3: Non-alcoholic beverages | P3: Prepared meals, snacks, sweets etc. | Q3: Food and beverages | R3: Pan, tobacco and intoxicants | S3: Clothing | T3: Footwear | U3: Clothing and footwear | V3: Housing | W3: Fuel and light | X3: Household goods and services | Y3: Health | Z3: Transport and communication | AA3: Recreation and amusement | AB3: Education | AC3: Personal care and effects | AD3: Miscellaneous | AE3: General index
B4: Rural | C4: 2023 | D4: May | E4: 173.2 | F4: 211.5 | G4: 171 | H4: 179.6 | I4: 173.3 | J4: 169 | K4: 148.7 | L4: 174.9 | M4: 121.9 | N4: 221 | O4: 178.7 | P4: 191.1 | Q4: 176.8 | R4: 199.9 | S4: 191.2 | T4: 187.9 | U4: 190.8 | V4: - | W4: 182.5 | X4: 179.8 | Y4: 187.8 | Z4: 169.7 | AA4: 173.8 | AB4: 180.3 | AC4: 184.9 | AD4: 179.5 | AE4: 179.8
B5: Urban | C5: 2023 | D5: May | E5: 174.7 | F5: 219.4 | G5: 176.7 | H5: 179.4 | I5: 164.4 | J5: 175.8 | K5: 185 | L5: 176.9 | M5: 124.2 | N5: 211.9 | O5: 165.9 | P5: 197.7 | Q5: 183.1 | R5: 204.2 | S5: 181.3 | T5: 168.1 | U5: 179.3 | V5: 175.6 | W5: 183.4 | X5: 170.1 | Y5: 182.2 | Z5: 160.4 | AA5: 169.2 | AB5: 174.8 | AC5: 185.6 | AD5: 171.6 | AE5: 178.2
B6: Rural+Urban | C6: 2023 | D6: May | E6: 173.7 | F6: 214.3 | G6: 173.2 | H6: 179.5 | I6: 170 | J6: 172.2 | K6: 161 | L6: 175.6 | M6: 122.7 | N6: 218 | O6: 173.4 | P6: 194.2 | Q6: 179.1 | R6: 201 | S6: 187.3 | T6: 179.7 | U6: 186.2 | V6: 175.6 | W6: 182.8 | X6: 175.2 | Y6: 185.7 | Z6: 164.8 | AA6: 171.2 | AB6: 177.1 | AC6: 185.2 | AD6: 175.7 | AE6: 179.1
C9: May'2023 | K9: May'2023
B10: Category | C10: Rural | D10: Urban | E10: Rural+Urban | F10: New Food Category | H10: New Food Category | I10: Rural | J10: Urban | K10: Rural+Urban | L10: Rural | M10: Urban | N10: Rural+Urban
B11: Cereals and products | C11: 173.2 | D11: 174.7 | E11: 173.7 | F11: Food | H11: Food | I11: =SUMIFS(C$11:C$37,$F$11:$F$37,$H11) -> 2099.6 | J11: =SUMIFS(D$11:D$37,$F$11:$F$37,$H11) -> 2137.4 | K11: =SUMIFS(E$11:E$37,$F$11:$F$37,$H11) -> 2112.7 | L11: =I11/$I$21 -> 0.46670223 | M11: =J11/$J$21 -> 0.46055722 | N11: =K11/$K$21 -> 0.45391458
B12: Meat and fish | C12: 211.5 | D12: 219.4 | E12: 214.3 | F12: Food | H12: Luxury | I12: =SUMIFS(C$11:C$37,$F$11:$F$37,$H12) -> 749.7 | J12: =SUMIFS(D$11:D$37,$F$11:$F$37,$H12) -> 756.7 | K12: =SUMIFS(E$11:E$37,$F$11:$F$37,$H12) -> 751.6 | L12: =I12/$I$21 -> 0.16664444 | M12: =J12/$J$21 -> 0.16305027 | N12: =K12/$K$21 -> 0.16148161
B13: Egg | C13: 171 | D13: 176.7 | E13: 173.2 | F13: Food | H13: Clothing | I13: =SUMIFS(C$11:C$37,$F$11:$F$37,$H13) -> 569.9 | J13: =SUMIFS(D$11:D$37,$F$11:$F$37,$H13) -> 528.7 | K13: =SUMIFS(E$11:E$37,$F$11:$F$37,$H13) -> 553.2 | L13: =I13/$I$21 -> 0.12667823 | M13: =J13/$J$21 -> 0.11392187 | N13: =K13/$K$21 -> 0.11885528
B14: Milk and products | C14: 179.6 | D14: 179.4 | E14: 179.5 | F14: Food | H14: Housing | I14: =SUMIFS(C$11:C$37,$F$11:$F$37,$H14) -> 179.8 | J14: =SUMIFS(D$11:D$37,$F$11:$F$37,$H14) -> 345.7 | K14: =SUMIFS(E$11:E$37,$F$11:$F$37,$H14) -> 350.8 | L14: =I14/$I$21 -> 0.039966213 | M14: =J14/$J$21 -> 0.074489862 | N14: =K14/$K$21 -> 0.075369543
B15: Oils and fats | C15: 173.3 | D15: 164.4 | E15: 170 | F15: Food | H15: Fuel and light | I15: =SUMIFS(C$11:C$37,$F$11:$F$37,$H15) -> 182.5 | J15: =SUMIFS(D$11:D$37,$F$11:$F$37,$H15) -> 183.4 | K15: =SUMIFS(E$11:E$37,$F$11:$F$37,$H15) -> 182.8 | L15: =I15/$I$21 -> 0.040566373 | M15: =J15/$J$21 -> 0.039518197 | N15: =K15/$K$21 -> 0.039274665
B16: Fruits | C16: 169 | D16: 175.8 | E16: 172.2 | F16: Food | H16: Health | I16: =SUMIFS(C$11:C$37,$F$11:$F$37,$H16) -> 187.8 | J16: =SUMIFS(D$11:D$37,$F$11:$F$37,$H16) -> 182.2 | K16: =SUMIFS(E$11:E$37,$F$11:$F$37,$H16) -> 185.7 | L16: =I16/$I$21 -> 0.041744465 | M16: =J16/$J$21 -> 0.039259626 | N16: =K16/$K$21 -> 0.039897731
B17: Vegetables | C17: 148.7 | D17: 185 | E17: 161 | F17: Food | H17: Transportation | I17: =SUMIFS(C$11:C$37,$F$11:$F$37,$H17) -> 169.7 | J17: =SUMIFS(D$11:D$37,$F$11:$F$37,$H17) -> 160.4 | K17: =SUMIFS(E$11:E$37,$F$11:$F$37,$H17) -> 164.8 | L17: =I17/$I$21 -> 0.03772117 | M17: =J17/$J$21 -> 0.034562262 | N17: =K17/$K$21 -> 0.035407356
B18: Pulses and products | C18: 174.9 | D18: 176.9 | E18: 175.6 | F18: Food | H18: Education | I18: =SUMIFS(C$11:C$37,$F$11:$F$37,$H18) -> 180.3 | J18: =SUMIFS(D$11:D$37,$F$11:$F$37,$H18) -> 174.8 | K18: =SUMIFS(E$11:E$37,$F$11:$F$37,$H18) -> 177.1 | L18: =I18/$I$21 -> 0.040077354 | M18: =J18/$J$21 -> 0.037665108 | N18: =K18/$K$21 -> 0.038050017
B19: Sugar and Confectionery | C19: 121.9 | D19: 124.2 | E19: 122.7 | F19: Food | H19: Other expenses | I19: =SUMIFS(C$11:C$37,$F$11:$F$37,$H19) -> 179.5 | J19: =SUMIFS(D$11:D$37,$F$11:$F$37,$H19) -> 171.6 | K19: =SUMIFS(E$11:E$37,$F$11:$F$37,$H19) -> 175.7 | L19: =I19/$I$21 -> 0.039899529 | M19: =J19/$J$21 -> 0.036975587 | N19: =K19/$K$21 -> 0.037749227
B20: Spices | C20: 221 | D20: 211.9 | E20: 218 | F20: Food | H20: GI | I20: =SUMIFS(C$11:C$37,$F$11:$F$37,$H20) -> 179.8 | J20: =SUMIFS(D$11:D$37,$F$11:$F$37,$H20) -> 178.2 | K20: =SUMIFS(E$11:E$37,$F$11:$F$37,$H20) -> 179.1
B21: Non-alcoholic beverages | C21: 178.7 | D21: 165.9 | E21: 173.4 | F21: Food | H21: Total (Exc GI) | I21: =SUM(I11:I19) -> 4498.8 | J21: =SUM(J11:J19) -> 4640.9 | K21: =SUM(K11:K19) -> 4654.4 | L21: =SUM(L11:L19) -> 1 | M21: =SUM(M11:M19) -> 1 | N21: =SUM(N11:N19) -> 1
B22: Prepared meals, snacks, sweets etc. | C22: 191.1 | D22: 197.7 | E22: 194.2 | F22: Luxury
B23: Food and beverages | C23: 176.8 | D23: 183.1 | E23: 179.1 | F23: Food
B24: Pan, tobacco and intoxicants | C24: 199.9 | D24: 204.2 | E24: 201 | F24: Luxury
B25: Clothing | C25: 191.2 | D25: 181.3 | E25: 187.3 | F25: Clothing
B26: Footwear | C26: 187.9 | D26: 168.1 | E26: 179.7 | F26: Clothing
B27: Clothing and footwear | C27: 190.8 | D27: 179.3 | E27: 186.2 | F27: Clothing
B28: Housing | C28: - | D28: 175.6 | E28: 175.6 | F28: Housing
B29: Fuel and light | C29: 182.5 | D29: 183.4 | E29: 182.8 | F29: Fuel and light
B30: Household goods and services | C30: 179.8 | D30: 170.1 | E30: 175.2 | F30: Housing
B31: Health | C31: 187.8 | D31: 182.2 | E31: 185.7 | F31: Health
B32: Transport and communication | C32: 169.7 | D32: 160.4 | E32: 164.8 | F32: Transportation
B33: Recreation and amusement | C33: 173.8 | D33: 169.2 | E33: 171.2 | F33: Luxury
B34: Education | C34: 180.3 | D34: 174.8 | E34: 177.1 | F34: Education
B35: Personal care and effects | C35: 184.9 | D35: 185.6 | E35: 185.2 | F35: Luxury
B36: Miscellaneous | C36: 179.5 | D36: 171.6 | E36: 175.7 | F36: Other expenses
B37: General index | C37: 179.8 | D37: 178.2 | E37: 179.1 | F37: GI
H43: Insight
H45: 1. Food has the highest contribution to CPI across all three categories, accounting for approximately 47% in Rural, 46% in Urban, and 45% in Rural + Urban areas.
H46: 2. Luxury is the second-largest contributor, accounting for approximately 17% in Rural, 16% in Urban, and 16% in Rural + Urban areas.
H47: 3. Clothing contributes approximately 13% in Rural, 11% in Urban, and 12% in Rural + Urban areas.
H48: 4. Housing has a higher contribution in Urban areas (7%) compared with Rural areas (4%), while the Rural + Urban contribution is approximately 8%.
...

Sheet 2.CPI YOY Analysis
G9: CPI Index and YoY Inflation — March Data
F10: Year | G10: Rural + Urban Index | H10: Rural Index | I10: Urban Index | J10: Rural + Urban YoY | K10: Rural YoY | L10: Urban YoY
F11: 2016 | G11: {=INDEX(Working_Data!$AD:$AD,MATCH(1,(Working_Data!$A:$A="Rural+Urban")*(Working_Data!$B:$B=$F11)*(Working_Data!$C:$C="March"),0))} -> 126 | H11: {=INDEX(Working_Data!$AD:$AD,MATCH(1,(Working_Data!$A:$A="Rural")*(Working_Data!$B:$B=$F11)*(Working_Data!$C:$C="March"),0))} -> 128 | I11: {=INDEX(Working_Data!$AD:$AD,MATCH(1,(Working_Data!$A:$A="Urban")*(Working_Data!$B:$B=$F11)*(Working_Data!$C:$C="March"),0))} -> 123.8 | J11: - | K11: - | L11: -
F12: 2017 | G12: {=INDEX(Working_Data!$AD:$AD,MATCH(1,(Working_Data!$A:$A="Rural+Urban")*(Working_Data!$B:$B=$F12)*(Working_Data!$C:$C="March"),0))} -> 130.9 | H12: {=INDEX(Working_Data!$AD:$AD,MATCH(1,(Working_Data!$A:$A="Rural")*(Working_Data!$B:$B=$F12)*(Working_Data!$C:$C="March"),0))} -> 132.8 | I12: {=INDEX(Working_Data!$AD:$AD,MATCH(1,(Working_Data!$A:$A="Urban")*(Working_Data!$B:$B=$F12)*(Working_Data!$C:$C="March"),0))} -> 128.7 | J12: =(G12-G11)/G11 -> 0.038888889 | K12: =(H12-H11)/H11 -> 0.0375 | L12: =(I12-I11)/I11 -> 0.039579968
F13: 2018 | G13: {=INDEX(Working_Data!$AD:$AD,MATCH(1,(Working_Data!$A:$A="Rural+Urban")*(Working_Data!$B:$B=$F13)*(Working_Data!$C:$C="March"),0))} -> 136.5 | H13: {=INDEX(Working_Data!$AD:$AD,MATCH(1,(Working_Data!$A:$A="Rural")*(Working_Data!$B:$B=$F13)*(Working_Data!$C:$C="March"),0))} -> 138.7 | I13: {=INDEX(Working_Data!$AD:$AD,MATCH(1,(Working_Data!$A:$A="Urban")*(Working_Data!$B:$B=$F13)*(Working_Data!$C:$C="March"),0))} -> 134 | J13: =(G13-G12)/G12 -> 0.042780749 | K13: =(H13-H12)/H12 -> 0.044427711 | L13: =(I13-I12)/I12 -> 0.041181041
F14: 2019 | G14: {=INDEX(Working_Data!$AD:$AD,MATCH(1,(Working_Data!$A:$A="Rural+Urban")*(Working_Data!$B:$B=$F14)*(Working_Data!$C:$C="March"),0))} -> 140.4 | H14: {=INDEX(Working_Data!$AD:$AD,MATCH(1,(Working_Data!$A:$A="Rural")*(Working_Data!$B:$B=$F14)*(Working_Data!$C:$C="March"),0))} -> 141.2 | I14: {=INDEX(Working_Data!$AD:$AD,MATCH(1,(Working_Data!$A:$A="Urban")*(Working_Data!$B:$B=$F14)*(Working_Data!$C:$C="March"),0))} -> 139.5 | J14: =(G14-G13)/G13 -> 0.028571429 | K14: =(H14-H13)/H13 -> 0.018024513 | L14: =(I14-I13)/I13 -> 0.041044776
F15: 2020 | G15: {=INDEX(Working_Data!$AD:$AD,MATCH(1,(Working_Data!$A:$A="Rural+Urban")*(Working_Data!$B:$B=$F15)*(Working_Data!$C:$C="March"),0))} -> 148.6 | H15: {=INDEX(Working_Data!$AD:$AD,MATCH(1,(Working_Data!$A:$A="Rural")*(Working_Data!$B:$B=$F15)*(Working_Data!$C:$C="March"),0))} -> 149.8 | I15: {=INDEX(Working_Data!$AD:$AD,MATCH(1,(Working_Data!$A:$A="Urban")*(Working_Data!$B:$B=$F15)*(Working_Data!$C:$C="March"),0))} -> 147.3 | J15: =(G15-G14)/G14 -> 0.058404558 | K15: =(H15-H14)/H14 -> 0.060906516 | L15: =(I15-I14)/I14 -> 0.055913978
F16: 2021 | G16: {=INDEX(Working_Data!$AD:$AD,MATCH(1,(Working_Data!$A:$A="Rural+Urban")*(Working_Data!$B:$B=$F16)*(Working_Data!$C:$C="March"),0))} -> 156.8 | H16: {=INDEX(Working_Data!$AD:$AD,MATCH(1,(Working_Data!$A:$A="Rural")*(Working_Data!$B:$B=$F16)*(Working_Data!$C:$C="March"),0))} -> 156.7 | I16: {=INDEX(Working_Data!$AD:$AD,MATCH(1,(Working_Data!$A:$A="Urban")*(Working_Data!$B:$B=$F16)*(Working_Data!$C:$C="March"),0))} -> 156.9 | J16: =(G16-G15)/G15 -> 0.055181696 | K16: =(H16-H15)/H15 -> 0.046061415 | L16: =(I16-I15)/I15 -> 0.065173116
F17: 2022 | G17: {=INDEX(Working_Data!$AD:$AD,MATCH(1,(Working_Data!$A:$A="Rural+Urban")*(Working_Data!$B:$B=$F17)*(Working_Data!$C:$C="March"),0))} -> 167.7 | H17: {=INDEX(Working_Data!$AD:$AD,MATCH(1,(Working_Data!$A:$A="Rural")*(Working_Data!$B:$B=$F17)*(Working_Data!$C:$C="March"),0))} -> 168.7 | I17: {=INDEX(Working_Data!$AD:$AD,MATCH(1,(Working_Data!$A:$A="Urban")*(Working_Data!$B:$B=$F17)*(Working_Data!$C:$C="March"),0))} -> 166.5 | J17: =(G17-G16)/G16 -> 0.069515306 | K17: =(H17-H16)/H16 -> 0.076579451 | L17: =(I17-I16)/I16 -> 0.061185468
F18: 2023 | G18: {=INDEX(Working_Data!$AD:$AD,MATCH(1,(Working_Data!$A:$A="Rural+Urban")*(Working_Data!$B:$B=$F18)*(Working_Data!$C:$C="March"),0))} -> 177.2 | H18: {=INDEX(Working_Data!$AD:$AD,MATCH(1,(Working_Data!$A:$A="Rural")*(Working_Data!$B:$B=$F18)*(Working_Data!$C:$C="March"),0))} -> 178 | I18: {=INDEX(Working_Data!$AD:$AD,MATCH(1,(Working_Data!$A:$A="Urban")*(Working_Data!$B:$B=$F18)*(Working_Data!$C:$C="March"),0))} -> 176.3 | J18: =(G18-G17)/G17 -> 0.056648778 | K18: =(H18-H17)/H17 -> 0.055127445 | L18: =(I18-I17)/I17 -> 0.058858859
F19: Reason for the Highest Inflation in 2022
F22: Insight: The highest Rural + Urban YoY inflation in the analysis was recorded in 2022 at 7.0%, based on March data. The increase was largely driven by supply-side shocks and higher global commodity prices following the Russia-Ukraine conflict. The RBI reported that food and beverages were the primary source of the inflation build-up in 2022-23, with higher global food prices, supply shortages and adverse weather conditions contributing significantly. Heat waves and uneven rainfall affected agricultural supply, while higher international energy prices increased fuel and transportation costs. This impact is also visible in the data: Rural YoY inflation increased from 4.6% in 2021 to 7.7% in 2022. The stronger rise in rural inflation is consistent with the significant role of food and agricultural supply shocks during this period.

Sheet 3.Food Inflation Analysis
E5: Monthly Food Bucket CPI and MoM Inflation (Jun-22 to May-23)
A6: Month | B6: Year | C6: Cereals and products | D6: Meat and fish | E6: Egg | F6: Milk and products | G6: Oils and fats | H6: Fruits | I6: Vegetables | J6: Pulses and products | K6: Sugar and Confectionery | L6: Spices | M6: Non-alcoholic beverages | N6: Food and beverages | O6: Food Bucket | P6: MoM Inflation
A7: June | B7: 2022 | C7: {=INDEX(Working_Data!$D:$AZ,MATCH(1,(Working_Data!$A:$A="Rural+Urban")*(Working_Data!$B:$B=$B7)*(Working_Data!$C:$C=$A7),0),MATCH(C$6,Working_Data!$D$1:$AZ$1,0))} -> 155 | D7: {=INDEX(Working_Data!$D:$AZ,MATCH(1,(Working_Data!$A:$A="Rural+Urban")*(Working_Data!$B:$B=$B7)*(Working_Data!$C:$C=$A7),0),MATCH(D$6,Working_Data!$D$1:$AZ$1,0))} -> 219.4 | E7: {=INDEX(Working_Data!$D:$AZ,MATCH(1,(Working_Data!$A:$A="Rural+Urban")*(Working_Data!$B:$B=$B7)*(Working_Data!$C:$C=$A7),0),MATCH(E$6,Working_Data!$D$1:$AZ$1,0))} -> 170.8 | F7: {=INDEX(Working_Data!$D:$AZ,MATCH(1,(Working_Data!$A:$A="Rural+Urban")*(Working_Data!$B:$B=$B7)*(Working_Data!$C:$C=$A7),0),MATCH(F$6,Working_Data!$D$1:$AZ$1,0))} -> 165.8 | G7: {=INDEX(Working_Data!$D:$AZ,MATCH(1,(Working_Data!$A:$A="Rural+Urban")*(Working_Data!$B:$B=$B7)*(Working_Data!$C:$C=$A7),0),MATCH(G$6,Working_Data!$D$1:$AZ$1,0))} -> 200.9 | H7: {=INDEX(Working_Data!$D:$AZ,MATCH(1,(Working_Data!$A:$A="Rural+Urban")*(Working_Data!$B:$B=$B7)*(Working_Data!$C:$C=$A7),0),MATCH(H$6,Working_Data!$D$1:$AZ$1,0))} -> 169.7 | I7: {=INDEX(Working_Data!$D:$AZ,MATCH(1,(Working_Data!$A:$A="Rural+Urban")*(Working_Data!$B:$B=$B7)*(Working_Data!$C:$C=$A7),0),MATCH(I$6,Working_Data!$D$1:$AZ$1,0))} -> 182.3 | J7: {=INDEX(Working_Data!$D:$AZ,MATCH(1,(Working_Data!$A:$A="Rural+Urban")*(Working_Data!$B:$B=$B7)*(Working_Data!$C:$C=$A7),0),MATCH(J$6,Working_Data!$D$1:$AZ$1,0))} -> 164.3 | ... N7: {=INDEX(Working_Data!$D:$AZ,MATCH(1,(Working_Data!$A:$A="Rural+Urban")*(Working_Data!$B:$B=$B7)*(Working_Data!$C:$C=$A7),0),MATCH(N$6,Working_Data!$D$1:$AZ$1,0))} -> 174.9 | O7: =SUM(C7:N7) -> 2078 | P7: -
A8: July | B8: 2022 | C8: {=INDEX(Working_Data!$D:$AZ,MATCH(1,(Working_Data!$A:$A="Rural+Urban")*(Working_Data!$B:$B=$B8)*(Working_Data!$C:$C=$A8),0),MATCH(C$6,Working_Data!$D$1:$AZ$1,0))} -> 156.5 | D8: {=INDEX(Working_Data!$D:$AZ,MATCH(1,(Working_Data!$A:$A="Rural+Urban")*(Working_Data!$B:$B=$B8)*(Working_Data!$C:$C=$A8),0),MATCH(D$6,Working_Data!$D$1:$AZ$1,0))} -> 213 | E8: {=INDEX(Working_Data!$D:$AZ,MATCH(1,(Working_Data!$A:$A="Rural+Urban")*(Working_Data!$B:$B=$B8)*(Working_Data!$C:$C=$A8),0),MATCH(E$6,Working_Data!$D$1:$AZ$1,0))} -> 175.2 | F8: {=INDEX(Working_Data!$D:$AZ,MATCH(1,(Working_Data!$A:$A="Rural+Urban")*(Working_Data!$B:$B=$B8)*(Working_Data!$C:$C=$A8),0),MATCH(F$6,Working_Data!$D$1:$AZ$1,0))} -> 166.6 | G8: {=INDEX(Working_Data!$D:$AZ,MATCH(1,(Working_Data!$A:$A="Rural+Urban")*(Working_Data!$B:$B=$B8)*(Working_Data!$C:$C=$A8),0),MATCH(G$6,Working_Data!$D$1:$AZ$1,0))} -> 195.8 | H8: {=INDEX(Working_Data!$D:$AZ,MATCH(1,(Working_Data!$A:$A="Rural+Urban")*(Working_Data!$B:$B=$B8)*(Working_Data!$C:$C=$A8),0),MATCH(H$6,Working_Data!$D$1:$AZ$1,0))} -> 174.2 | I8: {=INDEX(Working_Data!$D:$AZ,MATCH(1,(Working_Data!$A:$A="Rural+Urban")*(Working_Data!$B:$B=$B8)*(Working_Data!$C:$C=$A8),0),MATCH(I$6,Working_Data!$D$1:$AZ$1,0))} -> 182.1 | J8: {=INDEX(Working_Data!$D:$AZ,MATCH(1,(Working_Data!$A:$A="Rural+Urban")*(Working_Data!$B:$B=$B8)*(Working_Data!$C:$C=$A8),0),MATCH(J$6,Working_Data!$D$1:$AZ$1,0))} -> 164.3 | ... N8: {=INDEX(Working_Data!$D:$AZ,MATCH(1,(Working_Data!$A:$A="Rural+Urban")*(Working_Data!$B:$B=$B8)*(Working_Data!$C:$C=$A8),0),MATCH(N$6,Working_Data!$D$1:$AZ$1,0))} -> 175 | O8: =SUM(C8:N8) -> 2081.1 | P8: =(O8-O7)/O7 -> 0.0014918191
A9: August | B9: 2022 | C9: {=INDEX(Working_Data!$D:$AZ,MATCH(1,(Working_Data!$A:$A="Rural+Urban")*(Working_Data!$B:$B=$B9)*(Working_Data!$C:$C=$A9),0),MATCH(C$6,Working_Data!$D$1:$AZ$1,0))} -> 160.3 | D9: {=INDEX(Working_Data!$D:$AZ,MATCH(1,(Working_Data!$A:$A="Rural+Urban")*(Working_Data!$B:$B=$B9)*(Working_Data!$C:$C=$A9),0),MATCH(D$6,Working_Data!$D$1:$AZ$1,0))} -> 206.5 | E9: {=INDEX(Working_Data!$D:$AZ,MATCH(1,(Working_Data!$A:$A="Rural+Urban")*(Working_Data!$B:$B=$B9)*(Working_Data!$C:$C=$A9),0),MATCH(E$6,Working_Data!$D$1:$AZ$1,0))} -> 169.2 | F9: {=INDEX(Working_Data!$D:$AZ,MATCH(1,(Working_Data!$A:$A="Rural+Urban")*(Working_Data!$B:$B=$B9)*(Working_Data!$C:$C=$A9),0),MATCH(F$6,Working_Data!$D$1:$AZ$1,0))} -> 168.1 | G9: {=INDEX(Working_Data!$D:$AZ,MATCH(1,(Working_Data!$A:$A="Rural+Urban")*(Working_Data!$B:$B=$B9)*(Working_Data!$C:$C=$A9),0),MATCH(G$6,Working_Data!$D$1:$AZ$1,0))} -> 192.4 | H9: {=INDEX(Working_Data!$D:$AZ,MATCH(1,(Working_Data!$A:$A="Rural+Urban")*(Working_Data!$B:$B=$B9)*(Working_Data!$C:$C=$A9),0),MATCH(H$6,Working_Data!$D$1:$AZ$1,0))} -> 172.9 | I9: {=INDEX(Working_Data!$D:$AZ,MATCH(1,(Working_Data!$A:$A="Rural+Urban")*(Working_Data!$B:$B=$B9)*(Working_Data!$C:$C=$A9),0),MATCH(I$6,Working_Data!$D$1:$AZ$1,0))} -> 186.7 | J9: {=INDEX(Working_Data!$D:$AZ,MATCH(1,(Working_Data!$A:$A="Rural+Urban")*(Working_Data!$B:$B=$B9)*(Working_Data!$C:$C=$A9),0),MATCH(J$6,Working_Data!$D$1:$AZ$1,0))} -> 167.2 | ... N9: {=INDEX(Working_Data!$D:$AZ,MATCH(1,(Working_Data!$A:$A="Rural+Urban")*(Working_Data!$B:$B=$B9)*(Working_Data!$C:$C=$A9),0),MATCH(N$6,Working_Data!$D$1:$AZ$1,0))} -> 176.3 | O9: =SUM(C9:N9) -> 2082.9 | P9: =(O9-O8)/O8 -> 0.0008649272
A10: September | B10: 2022 | C10: {=INDEX(Working_Data!$D:$AZ,MATCH(1,(Working_Data!$A:$A="Rural+Urban")*(Working_Data!$B:$B=$B10)*(Working_Data!$C:$C=$A10),0),MATCH(C$6,Working_Data!$D$1:$AZ$1,0))} -> 163.5 | D10: {=INDEX(Working_Data!$D:$AZ,MATCH(1,(Working_Data!$A:$A="Rural+Urban")*(Working_Data!$B:$B=$B10)*(Working_Data!$C:$C=$A10),0),MATCH(D$6,Working_Data!$D$1:$AZ$1,0))} -> 209.2 | E10: {=INDEX(Working_Data!$D:$AZ,MATCH(1,(Working_Data!$A:$A="Rural+Urban")*(Working_Data!$B:$B=$B10)*(Working_Data!$C:$C=$A10),0),MATCH(E$6,Working_Data!$D$1:$AZ$1,0))} -> 169.7 | F10: {=INDEX(Working_Data!$D:$AZ,MATCH(1,(Working_Data!$A:$A="Rural+Urban")*(Working_Data!$B:$B=$B10)*(Working_Data!$C:$C=$A10),0),MATCH(F$6,Working_Data!$D$1:$AZ$1,0))} -> 169.7 | G10: {=INDEX(Working_Data!$D:$AZ,MATCH(1,(Working_Data!$A:$A="Rural+Urban")*(Working_Data!$B:$B=$B10)*(Working_Data!$C:$C=$A10),0),MATCH(G$6,Working_Data!$D$1:$AZ$1,0))} -> 188.7 | H10: {=INDEX(Working_Data!$D:$AZ,MATCH(1,(Working_Data!$A:$A="Rural+Urban")*(Working_Data!$B:$B=$B10)*(Working_Data!$C:$C=$A10),0),MATCH(H$6,Working_Data!$D$1:$AZ$1,0))} -> 165.7 | I10: {=INDEX(Working_Data!$D:$AZ,MATCH(1,(Working_Data!$A:$A="Rural+Urban")*(Working_Data!$B:$B=$B10)*(Working_Data!$C:$C=$A10),0),MATCH(I$6,Working_Data!$D$1:$AZ$1,0))} -> 191.8 | J10: {=INDEX(Working_Data!$D:$AZ,MATCH(1,(Working_Data!$A:$A="Rural+Urban")*(Working_Data!$B:$B=$B10)*(Working_Data!$C:$C=$A10),0),MATCH(J$6,Working_Data!$D$1:$AZ$1,0))} -> 169.1 | ... N10: {=INDEX(Working_Data!$D:$AZ,MATCH(1,(Working_Data!$A:$A="Rural+Urban")*(Working_Data!$B:$B=$B10)*(Working_Data!$C:$C=$A10),0),MATCH(N$6,Working_Data!$D$1:$AZ$1,0))} -> 177.8 | O10: =SUM(C10:N10) -> 2093.5 | P10: =(O10-O9)/O9 -> 0.0050890585
A11: October | B11: 2022 | C11: {=INDEX(Working_Data!$D:$AZ,MATCH(1,(Working_Data!$A:$A="Rural+Urban")*(Working_Data!$B:$B=$B11)*(Working_Data!$C:$C=$A11),0),MATCH(C$6,Working_Data!$D$1:$AZ$1,0))} -> 165.2 | D11: {=INDEX(Working_Data!$D:$AZ,MATCH(1,(Working_Data!$A:$A="Rural+Urban")*(Working_Data!$B:$B=$B11)*(Working_Data!$C:$C=$A11),0),MATCH(D$6,Working_Data!$D$1:$AZ$1,0))} -> 210.9 | E11: {=INDEX(Working_Data!$D:$AZ,MATCH(1,(Working_Data!$A:$A="Rural+Urban")*(Working_Data!$B:$B=$B11)*(Working_Data!$C:$C=$A11),0),MATCH(E$6,Working_Data!$D$1:$AZ$1,0))} -> 170.9 | F11: {=INDEX(Working_Data!$D:$AZ,MATCH(1,(Working_Data!$A:$A="Rural+Urban")*(Working_Data!$B:$B=$B11)*(Working_Data!$C:$C=$A11),0),MATCH(F$6,Working_Data!$D$1:$AZ$1,0))} -> 170.9 | G11: {=INDEX(Working_Data!$D:$AZ,MATCH(1,(Working_Data!$A:$A="Rural+Urban")*(Working_Data!$B:$B=$B11)*(Working_Data!$C:$C=$A11),0),MATCH(G$6,Working_Data!$D$1:$AZ$1,0))} -> 186.5 | H11: {=INDEX(Working_Data!$D:$AZ,MATCH(1,(Working_Data!$A:$A="Rural+Urban")*(Working_Data!$B:$B=$B11)*(Working_Data!$C:$C=$A11),0),MATCH(H$6,Working_Data!$D$1:$AZ$1,0))} -> 163.8 | I11: {=INDEX(Working_Data!$D:$AZ,MATCH(1,(Working_Data!$A:$A="Rural+Urban")*(Working_Data!$B:$B=$B11)*(Working_Data!$C:$C=$A11),0),MATCH(I$6,Working_Data!$D$1:$AZ$1,0))} -> 199.7 | J11: {=INDEX(Working_Data!$D:$AZ,MATCH(1,(Working_Data!$A:$A="Rural+Urban")*(Working_Data!$B:$B=$B11)*(Working_Data!$C:$C=$A11),0),MATCH(J$6,Working_Data!$D$1:$AZ$1,0))} -> 169.8 | ... N11: {=INDEX(Working_Data!$D:$AZ,MATCH(1,(Working_Data!$A:$A="Rural+Urban")*(Working_Data!$B:$B=$B11)*(Working_Data!$C:$C=$A11),0),MATCH(N$6,Working_Data!$D$1:$AZ$1,0))} -> 179.6 | O11: =SUM(C11:N11) -> 2109 | P11: =(O11-O10)/O10 -> 0.0074038691
A12: November | B12: 2022 | C12: {=INDEX(Working_Data!$D:$AZ,MATCH(1,(Working_Data!$A:$A="Rural+Urban")*(Working_Data!$B:$B=$B12)*(Working_Data!$C:$C=$A12),0),MATCH(C$6,Working_Data!$D$1:$AZ$1,0))} -> 167.4 | D12: {=INDEX(Working_Data!$D:$AZ,MATCH(1,(Working_Data!$A:$A="Rural+Urban")*(Working_Data!$B:$B=$B12)*(Working_Data!$C:$C=$A12),0),MATCH(D$6,Working_Data!$D$1:$AZ$1,0))} -> 209.4 | E12: {=INDEX(Working_Data!$D:$AZ,MATCH(1,(Working_Data!$A:$A="Rural+Urban")*(Working_Data!$B:$B=$B12)*(Working_Data!$C:$C=$A12),0),MATCH(E$6,Working_Data!$D$1:$AZ$1,0))} -> 181.4 | F12: {=INDEX(Working_Data!$D:$AZ,MATCH(1,(Working_Data!$A:$A="Rural+Urban")*(Working_Data!$B:$B=$B12)*(Working_Data!$C:$C=$A12),0),MATCH(F$6,Working_Data!$D$1:$AZ$1,0))} -> 172.3 | G12: {=INDEX(Working_Data!$D:$AZ,MATCH(1,(Working_Data!$A:$A="Rural+Urban")*(Working_Data!$B:$B=$B12)*(Working_Data!$C:$C=$A12),0),MATCH(G$6,Working_Data!$D$1:$AZ$1,0))} -> 188.9 | H12: {=INDEX(Working_Data!$D:$AZ,MATCH(1,(Working_Data!$A:$A="Rural+Urban")*(Working_Data!$B:$B=$B12)*(Working_Data!$C:$C=$A12),0),MATCH(H$6,Working_Data!$D$1:$AZ$1,0))} -> 160.7 | I12: {=INDEX(Working_Data!$D:$AZ,MATCH(1,(Working_Data!$A:$A="Rural+Urban")*(Working_Data!$B:$B=$B12)*(Working_Data!$C:$C=$A12),0),MATCH(I$6,Working_Data!$D$1:$AZ$1,0))} -> 183.1 | J12: {=INDEX(Working_Data!$D:$AZ,MATCH(1,(Working_Data!$A:$A="Rural+Urban")*(Working_Data!$B:$B=$B12)*(Working_Data!$C:$C=$A12),0),MATCH(J$6,Working_Data!$D$1:$AZ$1,0))} -> 170.5 | ... N12: {=INDEX(Working_Data!$D:$AZ,MATCH(1,(Working_Data!$A:$A="Rural+Urban")*(Working_Data!$B:$B=$B12)*(Working_Data!$C:$C=$A12),0),MATCH(N$6,Working_Data!$D$1:$AZ$1,0))} -> 178.3 | O12: =SUM(C12:N12) -> 2107.3 | P12: =(O12-O11)/O11 -> -0.00080606923
A13: December | B13: 2022 | C13: {=INDEX(Working_Data!$D:$AZ,MATCH(1,(Working_Data!$A:$A="Rural+Urban")*(Working_Data!$B:$B=$B13)*(Working_Data!$C:$C=$A13),0),MATCH(C$6,Working_Data!$D$1:$AZ$1,0))} -> 169.2 | D13: {=INDEX(Working_Data!$D:$AZ,MATCH(1,(Working_Data!$A:$A="Rural+Urban")*(Working_Data!$B:$B=$B13)*(Working_Data!$C:$C=$A13),0),MATCH(D$6,Working_Data!$D$1:$AZ$1,0))} -> 209 | E13: {=INDEX(Working_Data!$D:$AZ,MATCH(1,(Working_Data!$A:$A="Rural+Urban")*(Working_Data!$B:$B=$B13)*(Working_Data!$C:$C=$A13),0),MATCH(E$6,Working_Data!$D$1:$AZ$1,0))} -> 190.2 | F13: {=INDEX(Working_Data!$D:$AZ,MATCH(1,(Working_Data!$A:$A="Rural+Urban")*(Working_Data!$B:$B=$B13)*(Working_Data!$C:$C=$A13),0),MATCH(F$6,Working_Data!$D$1:$AZ$1,0))} -> 173.6 | G13: {=INDEX(Working_Data!$D:$AZ,MATCH(1,(Working_Data!$A:$A="Rural+Urban")*(Working_Data!$B:$B=$B13)*(Working_Data!$C:$C=$A13),0),MATCH(G$6,Working_Data!$D$1:$AZ$1,0))} -> 188.5 | H13: {=INDEX(Working_Data!$D:$AZ,MATCH(1,(Working_Data!$A:$A="Rural+Urban")*(Working_Data!$B:$B=$B13)*(Working_Data!$C:$C=$A13),0),MATCH(H$6,Working_Data!$D$1:$AZ$1,0))} -> 158 | I13: {=INDEX(Working_Data!$D:$AZ,MATCH(1,(Working_Data!$A:$A="Rural+Urban")*(Working_Data!$B:$B=$B13)*(Working_Data!$C:$C=$A13),0),MATCH(I$6,Working_Data!$D$1:$AZ$1,0))} -> 159.9 | J13: {=INDEX(Working_Data!$D:$AZ,MATCH(1,(Working_Data!$A:$A="Rural+Urban")*(Working_Data!$B:$B=$B13)*(Working_Data!$C:$C=$A13),0),MATCH(J$6,Working_Data!$D$1:$AZ$1,0))} -> 170.8 | ... N13: {=INDEX(Working_Data!$D:$AZ,MATCH(1,(Working_Data!$A:$A="Rural+Urban")*(Working_Data!$B:$B=$B13)*(Working_Data!$C:$C=$A13),0),MATCH(N$6,Working_Data!$D$1:$AZ$1,0))} -> 175.9 | O13: =SUM(C13:N13) -> 2093.1 | P13: =(O13-O12)/O12 -> -0.0067384805
A14: January | B14: 2023 | C14: {=INDEX(Working_Data!$D:$AZ,MATCH(1,(Working_Data!$A:$A="Rural+Urban")*(Working_Data!$B:$B=$B14)*(Working_Data!$C:$C=$A14),0),MATCH(C$6,Working_Data!$D$1:$AZ$1,0))} -> 173.8 | D14: {=INDEX(Working_Data!$D:$AZ,MATCH(1,(Working_Data!$A:$A="Rural+Urban")*(Working_Data!$B:$B=$B14)*(Working_Data!$C:$C=$A14),0),MATCH(D$6,Working_Data!$D$1:$AZ$1,0))} -> 210.7 | E14: {=INDEX(Working_Data!$D:$AZ,MATCH(1,(Working_Data!$A:$A="Rural+Urban")*(Working_Data!$B:$B=$B14)*(Working_Data!$C:$C=$A14),0),MATCH(E$6,Working_Data!$D$1:$AZ$1,0))} -> 194.5 | F14: {=INDEX(Working_Data!$D:$AZ,MATCH(1,(Working_Data!$A:$A="Rural+Urban")*(Working_Data!$B:$B=$B14)*(Working_Data!$C:$C=$A14),0),MATCH(F$6,Working_Data!$D$1:$AZ$1,0))} -> 174.6 | G14: {=INDEX(Working_Data!$D:$AZ,MATCH(1,(Working_Data!$A:$A="Rural+Urban")*(Working_Data!$B:$B=$B14)*(Working_Data!$C:$C=$A14),0),MATCH(G$6,Working_Data!$D$1:$AZ$1,0))} -> 187.2 | H14: {=INDEX(Working_Data!$D:$AZ,MATCH(1,(Working_Data!$A:$A="Rural+Urban")*(Working_Data!$B:$B=$B14)*(Working_Data!$C:$C=$A14),0),MATCH(H$6,Working_Data!$D$1:$AZ$1,0))} -> 158.3 | I14: {=INDEX(Working_Data!$D:$AZ,MATCH(1,(Working_Data!$A:$A="Rural+Urban")*(Working_Data!$B:$B=$B14)*(Working_Data!$C:$C=$A14),0),MATCH(I$6,Working_Data!$D$1:$AZ$1,0))} -> 153.9 | J14: {=INDEX(Working_Data!$D:$AZ,MATCH(1,(Working_Data!$A:$A="Rural+Urban")*(Working_Data!$B:$B=$B14)*(Working_Data!$C:$C=$A14),0),MATCH(J$6,Working_Data!$D$1:$AZ$1,0))} -> 170.9 | ... N14: {=INDEX(Working_Data!$D:$AZ,MATCH(1,(Working_Data!$A:$A="Rural+Urban")*(Working_Data!$B:$B=$B14)*(Working_Data!$C:$C=$A14),0),MATCH(N$6,Working_Data!$D$1:$AZ$1,0))} -> 176.7 | O14: =SUM(C14:N14) -> 2101.5 | P14: =(O14-O13)/O13 -> 0.0040131862
A15: February | B15: 2023 | C15: {=INDEX(Working_Data!$D:$AZ,MATCH(1,(Working_Data!$A:$A="Rural+Urban")*(Working_Data!$B:$B=$B15)*(Working_Data!$C:$C=$A15),0),MATCH(C$6,Working_Data!$D$1:$AZ$1,0))} -> 174.4 | D15: {=INDEX(Working_Data!$D:$AZ,MATCH(1,(Working_Data!$A:$A="Rural+Urban")*(Working_Data!$B:$B=$B15)*(Working_Data!$C:$C=$A15),0),MATCH(D$6,Working_Data!$D$1:$AZ$1,0))} -> 207.7 | E15: {=INDEX(Working_Data!$D:$AZ,MATCH(1,(Working_Data!$A:$A="Rural+Urban")*(Working_Data!$B:$B=$B15)*(Working_Data!$C:$C=$A15),0),MATCH(E$6,Working_Data!$D$1:$AZ$1,0))} -> 175.2 | F15: {=INDEX(Working_Data!$D:$AZ,MATCH(1,(Working_Data!$A:$A="Rural+Urban")*(Working_Data!$B:$B=$B15)*(Working_Data!$C:$C=$A15),0),MATCH(F$6,Working_Data!$D$1:$AZ$1,0))} -> 177.3 | G15: {=INDEX(Working_Data!$D:$AZ,MATCH(1,(Working_Data!$A:$A="Rural+Urban")*(Working_Data!$B:$B=$B15)*(Working_Data!$C:$C=$A15),0),MATCH(G$6,Working_Data!$D$1:$AZ$1,0))} -> 179.3 | H15: {=INDEX(Working_Data!$D:$AZ,MATCH(1,(Working_Data!$A:$A="Rural+Urban")*(Working_Data!$B:$B=$B15)*(Working_Data!$C:$C=$A15),0),MATCH(H$6,Working_Data!$D$1:$AZ$1,0))} -> 169.5 | I15: {=INDEX(Working_Data!$D:$AZ,MATCH(1,(Working_Data!$A:$A="Rural+Urban")*(Working_Data!$B:$B=$B15)*(Working_Data!$C:$C=$A15),0),MATCH(I$6,Working_Data!$D$1:$AZ$1,0))} -> 152.7 | J15: {=INDEX(Working_Data!$D:$AZ,MATCH(1,(Working_Data!$A:$A="Rural+Urban")*(Working_Data!$B:$B=$B15)*(Working_Data!$C:$C=$A15),0),MATCH(J$6,Working_Data!$D$1:$AZ$1,0))} -> 171 | ... N15: {=INDEX(Working_Data!$D:$AZ,MATCH(1,(Working_Data!$A:$A="Rural+Urban")*(Working_Data!$B:$B=$B15)*(Working_Data!$C:$C=$A15),0),MATCH(N$6,Working_Data!$D$1:$AZ$1,0))} -> 177 | O15: =SUM(C15:N15) -> 2086.1 | P15: =(O15-O14)/O14 -> -0.007328099
